<mujoco model="floating">
	<actuator>
        <!-- Physical limits of the actuator. -->
        <motor ctrllimited="true" ctrlrange="-80.0 80.0" joint="joint1" name="torq_j1"/>
        <motor ctrllimited="true" ctrlrange="-80.0 80.0" joint="joint2" name="torq_j2"/>
        <motor ctrllimited="true" ctrlrange="-80.0 80.0" joint="joint3" name="torq_j3"/>
    </actuator>
<worldbody>
	<body name="base" pos="0 0 0">
		<inertial pos="0 0 0" mass="3" diaginertia="0.3 0.3 0.3" />
        <joint name="joint1" type="slide" pos="0 0 0" axis="0 0 1" limited="true" range="0 0.01" damping="50"/>
        <joint name="joint2" type="slide" pos="0 0 0" axis="0 1 0" limited="true" range="-.2 .2" damping="50"/>
        <joint name="joint3" type="slide" pos="0 0 0" axis="1 0 0" limited="true" range="-.2 .2" damping="50"/>
        <body name="right_hand" pos="0 0 .86">
        	<inertial pos="0 0 0" mass="3" diaginertia="0.3 0.3 0.3" />
       	</body>
    </body>
</worldbody>
</mujoco>